Workbook

Sheet UserChat
A1: id | B1: managedAt | C1: 법인명 | D1: 사업자번호 | E1: name | F1: title | G1: description | H1: summarizedMessage | I1: tags | J1: priority | K1: direction | L1: sync | M1: page | N1: userId | O1: assigneeId | P1: firstAssigneeId | Q1: assigneeIdAtFirstClose | R1: managerIds | S1: teamId | T1: mediumType | U1: mediumName | V1: mediumSenderName | W1: state | X1: missedReason | Y1: goalState | Z1: goalCheckedAt | AA1: everOpened | AB1: reopened | AC1: reassigned | AD1: workflowTriggered | AE1: alfTriggered | AF1: replyCount | AG1: replyCountInOperation | AH1: reopenCount | AI1: reassignmentCount | AJ1: createdAt | AK1: updatedAt | AL1: firstWorkflowStartedAt | AM1: firstAskedAt | AN1: firstAlfStartedAt | AO1: firstAlfEndedAt | AP1: firstWorkflowEndedAt | AQ1: firstQueueInAt | AR1: queuedAt | AS1: firstQueueOutAt | AT1: firstOpenedAt | AU1: openedAt | AV1: firstMissedAt | AW1: missedAt | AX1: firstAssignedAt | AY1: firstActiveAt | AZ1: firstAnsweredAt | BA1: repliedAt | BB1: snoozedAt | BC1: firstClosedAt | BD1: closedAt | BE1: totalReplyTime | BF1: totalReplyTimeInOperation | BG1: avgReplyTime | BH1: avgReplyTimeInOperation | BI1: totalSnoozedTime | BJ1: totalSnoozedTimeInOperation | BK1: firstQueueTime | BL1: firstQueueTimeInOperation | BM1: timeToFirstAssignment | BN1: timeToFirstAssignmentInOperation | BO1: timeToFirstAnswer | BP1: timeToFirstAnswerInOperation | BQ1: timeFromFirstAskToFirstAnswer | BR1: timeFromFirstAskToFirstAnswerInOperation | BS1: timeFromFirstAssignmentToFirstAnswer | BT1: timeFromFirstAssignmentToFirstAnswerInOperation | BU1: timeFromFirstActiveToFirstAnswer | BV1: timeFromFirstActiveToFirstAnswerInOperation | BW1: timeFromFirstOpenToFirstAnswer | BX1: timeFromFirstOpenToFirstAnswerInOperation | BY1: timeToFirstClose | BZ1: timeToFirstCloseInOperation | CA1: timeToClose | CB1: timeToCloseInOperation | CC1: timeFromFirstAskToFirstClose | CD1: timeFromFirstAskToFirstCloseInOperation | CE1: timeFromFirstAssignmentToFirstClose | CF1: timeFromFirstAssignmentToFirstCloseInOperation | CG1: timeFromFirstActiveToFirstClose | CH1: timeFromFirstActiveToFirstCloseInOperation | CI1: timeFromFirstOpenToFirstClose | CJ1: timeFromFirstOpenToFirstCloseInOperation | CK1: memberHandlingTime | CL1: memberHandlingTimeInOperation | CM1: firstMemberHandlingTime | CN1: firstMemberHandlingTimeInOperation | CO1: workflowHandlingTime | CP1: alfHandlingTime | CQ1: alfCxScore | CR1: url | CS1: profile.csat | CT1: profile.csatComment
A2: 6996f5f607c5323d04fc | B2: 46072.859 | C2: {=INDEX('User data'!E:E, MATCH(E2, 'User data'!B:B, 0))} -> 주식회사 나우고 (NOWGO) | D2: {=INDEX('User data'!F:F, MATCH(C2, 'User data'!E:E, 0))} -> 753-87-03437 | E2: 김지원 | J2: medium | K2: INBOUND | L2: FALSE | M2: https://www.gowid.com | N2: 69965e75e7898f2d426e | T2: native | W2: initial | Y2: waiting | AA2: FALSE | AB2: FALSE | AC2: FALSE | AD2: FALSE | AE2: TRUE | AJ2: 46072.859 | AK2: 46072.86 | AM2: 46072.859 | AN2: 46072.859 | CR2: https://desk.channel.io/gowid/user-chats/6996f5f607c5323d04fc
A3: 6996e18029ec011e9717 | B3: 46072.799 | C3: {=INDEX('User data'!E:E, MATCH(E3, 'User data'!B:B, 0))} | D3: {=INDEX('User data'!F:F, MATCH(C3, 'User data'!E:E, 0))} -> #N/A | E3: 베이글 219 | J3: medium | K3: INBOUND | L3: FALSE | M3: https://www.gowid.com | N3: 6996e0e650385b354543 | T3: native | W3: initial | Y3: waiting | AA3: FALSE | AB3: FALSE | AC3: FALSE | AD3: FALSE | AE3: TRUE | AJ3: 46072.799 | AK3: 46072.799 | AM3: 46072.799 | AN3: 46072.799 | CR3: https://desk.channel.io/gowid/user-chats/6996e18029ec011e9717
A4: 6996e105f22aec26e769 | B4: 46072.797 | C4: {=INDEX('User data'!E:E, MATCH(E4, 'User data'!B:B, 0))} -> 주식회사 제이엔케이글로벌 (JNK GLOBAL Inc) | D4: {=INDEX('User data'!F:F, MATCH(C4, 'User data'!E:E, 0))} -> 393-87-02181 | E4: 최진주 | H4: [상담요약] - 고객사: 고위드 - 문의요약: 고위드 탈퇴 요청 - 문의유형: 해지 - impact: L2 - 처리내용: 고객 탈퇴 절차 안내, 의견 수렴 - 결과: 상담 종료 - 후속조치: 유선 연락 예정, 탈퇴 절차 진행 | I4: 탈회·탈퇴 | J4: medium | K4: INBOUND | L4: FALSE | M4: https://www.gowid.com | N4: 6996e0ba1115cac5d834 | O4: 607950 | P4: 607950 | Q4: 607950 | R4: 594863, 607950 | T4: native | W4: closed | Y4: none | AA4: TRUE | AB4: FALSE | AC4: FALSE | AD4: TRUE | AE4: TRUE | AF4: 6 | AG4: 5 | AJ4: 46072.797 | AK4: 46073.576 | AL4: 46072.797 | AM4: 46072.797 | AN4: 46072.797 | AO4: 46072.797 | AP4: 46072.797 | AT4: 46072.797 | AU4: 46072.797 | AX4: 46073.42 | AY4: 46072.797 | AZ4: 46073.42 | BA4: 46073.473 | BC4: 46073.576 | BD4: 46073.576 | BE4: 56782 | BF4: 3043 | BG4: 9463 | BH4: 608 | BM4: 53750 | BN4: 246 | BO4: 53754 | BP4: 251 | BQ4: 53755 | BR4: 251 | BS4: 4 | BT4: 4 | BU4: 53752 | BV4: 251 | BW4: 53752 | BX4: 251 | BY4: 67259 | BZ4: 10156 | CA4: 67259 | CB4: 10156 | CC4: 67259 | CD4: 10156 | CE4: 13509 | CF4: 9909 | CG4: 67256 | CH4: 10156 | CI4: 67256 | CJ4: 10156 | CK4: 67256 | CL4: 10156 | CM4: 67256 | CN4: 10156 | CO4: 2 | CP4: 2 | CR4: https://desk.channel.io/gowid/user-chats/6996e105f22aec26e769
A5: 6996de144eda6fa56870 | B5: 46072.789 | C5: {=INDEX('User data'!E:E, MATCH(E5, 'User data'!B:B, 0))} -> 주식회사 로이드케이 | D5: {=INDEX('User data'!F:F, MATCH(C5, 'User data'!E:E, 0))} -> 120-87-67951 | E5: 권대화 | J5: medium | K5: INBOUND | L5: FALSE | M5: https://www.gowid.com | N5: 68db916bd8428156f1aa | T5: native | W5: initial | Y5: waiting | AA5: FALSE | AB5: FALSE | AC5: FALSE | AD5: FALSE | AE5: TRUE | AJ5: 46072.789 | AK5: 46072.789 | AM5: 46072.789 | AN5: 46072.789 | CR5: https://desk.channel.io/gowid/user-chats/6996de144eda6fa56870
A6: 6996d57bbaa55f0e7c31 | B6: 46072.763 | C6: {=INDEX('User data'!E:E, MATCH(E6, 'User data'!B:B, 0))} -> 주식회사 보살핌 | D6: {=INDEX('User data'!F:F, MATCH(C6, 'User data'!E:E, 0))} -> 440-88-02179 | E6: 장한솔 | H6: [상담요약] - 고객사: 고위드 - 문의요약: 법인 카드 결제 문제 - 문의유형: 결제 관련 - impact: L1 - 처리내용: 카드 결제가 되지 않음, 한도 심사 완료 - 결과: 담당자 안내 후 문제 해결 여부 확인 - 후속조치: 추가 문의는 새 창에서 요청 | I6: 카드/한도상하향/오류 | J6: medium | K6: INBOUND | L6: FALSE | M6: https://www.gowid.com | N6: 67049b48d2f96f870032 | O6: 574085 | P6: 574085 | Q6: 574085 | R6: 540030, 574085, 607950 | S6: 13285 | T6: native | W6: closed | Y6: none | AA6: TRUE | AB6: FALSE | AC6: FALSE | AD6: TRUE | AE6: TRUE | AF6: 1 | AJ6: 46072.763 | AK6: 46073.492 | AL6: 46072.764 | AM6: 46072.763 | AN6: 46072.763 | AO6: 46072.764 | AP6: 46072.764 | AQ6: 46072.764 | AS6: 46072.764 | AT6: 46072.764 | AU6: 46072.764 | AX6: 46072.764 | AY6: 46072.764 | AZ6: 46072.827 | BA6: 46072.827 | BC6: 46073.45 | BD6: 46073.45 | BE6: 5454 | BG6: 5454 | BK6: 1 | BL6: 0 | BM6: 37 | BN6: 0 | BO6: 5490 | BP6: 0 | BQ6: 5490 | BR6: 0 | BS6: 5453 | BT6: 0 | BU6: 5453 | BV6: 0 | BW6: 5454 | BX6: 0 | BY6: 59359 | BZ6: 2908 | CA6: 59359 | CB6: 2908 | CC6: 59359 | CD6: 2908 | CE6: 59321 | CF6: 2908 | CG6: 59321 | CH6: 2908 | CI6: 59322 | CJ6: 2908 | CK6: 59321 | CL6: 2908 | CM6: 59321 | CN6: 2908 | CO6: 3 | CP6: 35 | CR6: https://desk.channel.io/gowid/user-chats/6996d57bbaa55f0e7c31
A7: 6996ce7029650198cbd4 | B7: 46072.742 | C7: {=INDEX('User data'!E:E, MATCH(E7, 'User data'!B:B, 0))} -> 주식회사 스티커스코퍼레이션 | D7: {=INDEX('User data'!F:F, MATCH(C7, 'User data'!E:E, 0))} -> 737-81-01527 | E7: 신혜서 | J7: medium | K7: INBOUND | L7: FALSE | M7: https://www.gowid.com | N7: 686b52afe94e86d525a9 | T7: native | W7: initial | Y7: waiting | AA7: FALSE | AB7: FALSE | AC7: FALSE | AD7: FALSE | AE7: TRUE | AJ7: 46072.742 | AK7: 46072.742 | AM7: 46072.742 | AN7: 46072.742 | CR7: https://desk.channel.io/gowid/user-chats/6996ce7029650198cbd4
A8: 6996cd3338319030d407 | B8: 46072.739 | C8: {=INDEX('User data'!E:E, MATCH(E8, 'User data'!B:B, 0))} -> 주식회사 파인우드리빙 | D8: {=INDEX('User data'!F:F, MATCH(C8, 'User data'!E:E, 0))} -> 819-86-01256 | E8: 박지민 | J8: medium | K8: INBOUND | L8: FALSE | M8: https://www.gowid.com | N8: 67f4efbd2d771506b220 | T8: native | W8: initial | Y8: waiting | AA8: FALSE | AB8: FALSE | AC8: FALSE | AD8: FALSE | AE8: TRUE | AJ8: 46072.739 | AK8: 46072.739 | AM8: 46072.739 | AN8: 46072.739 | CR8: https://desk.channel.io/gowid/user-chats/6996cd3338319030d407
A9: 697c672b52de5a403c86 | B9: 46072.733 | C9: {=INDEX('User data'!E:E, MATCH(E9, 'User data'!B:B, 0))} -> 주식회사 커들리스튜디오 | D9: {=INDEX('User data'!F:F, MATCH(C9, 'User data'!E:E, 0))} -> 636-88-02713 | E9: 유화연 | H9: [상담요약] - 고객사: 고위드 - 문의요약: 회사 사무실 관리비 카드 자동 납부 가능 여부 - 문의유형: 카드 이용 관련 - impact: L2 - 처리내용: 자동 납부 기능 신청 불가 안내, 신한카드 고객센터 번호 제공 - 결과: 문제 해결 방법 안내 - 후속조치: 추가 문의 가능 안내 | I9: 지출관리/카드관리 | J9: medium | K9: INBOUND | L9: FALSE | M9: https://www.gowid.com | N9: 681b3720f177b6c20783 | O9: 574085 | P9: 574085 | Q9: 574085 | R9: 574085, 607950 | S9: 13285 | T9: native | W9: closed | Y9: none | AA9: TRUE | AB9: FALSE | AC9: FALSE | AD9: TRUE | AE9: TRUE | AF9: 1 | AJ9: 46052.715 | AK9: 46073.499 | AL9: 46052.715 | AM9: 46052.715 | AN9: 46072.733 | AO9: 46072.734 | AP9: 46072.734 | AQ9: 46072.734 | AS9: 46072.734 | AT9: 46072.734 | AU9: 46072.734 | AX9: 46072.734 | AY9: 46072.734 | AZ9: 46073.421 | BA9: 46073.421 | BC9: 46073.458 | BD9: 46073.458 | BE9: 59351 | BG9: 59351 | BK9: 0 | BL9: 0 | BM9: 115 | BN9: 0 | BO9: 59466 | BP9: 385 | BQ9: 1789028 | BR9: 302785 | BS9: 59350 | BT9: 385 | BU9: 59350 | BV9: 385 | BW9: 59351 | BX9: 385 | BY9: 62613 | BZ9: 3533 | CA9: 62613 | CB9: 3533 | CC9: 1792176 | CD9: 305933 | CE9: 62497 | CF9: 3533 | CG9: 62497 | CH9: 3533 | CI9: 62498 | CJ9: 3533 | CK9: 62497 | CL9: 3533 | CM9: 62497 | CN9: 3533 | CO9: 1729678 | CP9: 114 | CR9: https://desk.channel.io/gowid/user-chats/697c672b52de5a403c86
A10: 6996cb0be0a6e6c19f53 | B10: 46072.732 | C10: {=INDEX('User data'!E:E, MATCH(E10, 'User data'!B:B, 0))} | D10: {=INDEX('User data'!F:F, MATCH(C10, 'User data'!E:E, 0))} -> #N/A | E10: 풋볼 754 | I10: 신규발급(오류) | J10: medium | K10: INBOUND | L10: FALSE | M10: https://www.gowid.com | N10: 6996c313ed0bfe931579 | O10: 607950 | P10: 607950 | R10: 607950 | T10: native | W10: opened | Y10: none | AA10: TRUE | AB10: FALSE | AC10: FALSE | AD10: FALSE | AE10: TRUE | AF10: 1 | AJ10: 46072.732 | AK10: 46073.571 | AM10: 46072.732 | AN10: 46072.732 | AO10: 46072.733 | AT10: 46072.733 | AU10: 46072.733 | AX10: 46072.732 | AY10: 46072.733 | AZ10: 46072.733 | BA10: 46073.421 | BE10: 59458 | BG10: 59458 | BM10: 7 | BN10: 0 | BO10: 17 | BP10: 0 | BQ10: 17 | BR10: 0 | BS10: 10 | BT10: 0 | BW10: 0 | CP10: 17 | CR10: https://desk.channel.io/gowid/user-chats/6996cb0be0a6e6c19f53
A11: 6996c38339acf66f73db | B11: 46072.71 | C11: {=INDEX('User data'!E:E, MATCH(E11, 'User data'!B:B, 0))} | D11: {=INDEX('User data'!F:F, MATCH(C11, 'User data'!E:E, 0))} -> #N/A | E11: 우산 411 | J11: medium | K11: INBOUND | L11: FALSE | M11: https://www.gowid.com | N11: 6996a9d33aac31bd8158 | T11: native | W11: initial | Y11: waiting | AA11: FALSE | AB11: FALSE | AC11: FALSE | AD11: FALSE | AE11: TRUE | AJ11: 46072.71 | AK11: 46072.712 | AM11: 46072.71 | AN11: 46072.71 | CR11: https://desk.channel.io/gowid/user-chats/6996c38339acf66f73db
A12: 6996b9fb528495ca8c69 | B12: 46072.682 | C12: {=INDEX('User data'!E:E, MATCH(E12, 'User data'!B:B, 0))} -> 주식회사 앳홈 | D12: {=INDEX('User data'!F:F, MATCH(C12, 'User data'!E:E, 0))} -> 136-81-34676 | E12: 이상희 | H12: 문의 내용이 15글자 이하이므로 요약할 내용이 없습니다. | J12: medium | K12: INBOUND | L12: FALSE | M12: https://www.gowid.com | N12: 698c0ad19c6b7bb05487 | T12: native | W12: closed | Y12: waiting | AA12: FALSE | AB12: FALSE | AC12: FALSE | AD12: FALSE | AE12: TRUE | AJ12: 46072.682 | AK12: 46072.682 | AM12: 46072.682 | AN12: 46072.682 | BC12: 46072.682 | BD12: 46072.682 | BY12: 29 | BZ12: 29 | CA12: 29 | CB12: 29 | CC12: 29 | CD12: 29 | CR12: https://desk.channel.io/gowid/user-chats/6996b9fb528495ca8c69
A13: 6996b8ff711dff23d7ae | B13: 46072.679 | C13: {=INDEX('User data'!E:E, MATCH(E13, 'User data'!B:B, 0))} -> (주)쿨스쿨 | D13: {=INDEX('User data'!F:F, MATCH(C13, 'User data'!E:E, 0))} -> 314-86-66749 | E13: 오진연 | J13: medium | K13: INBOUND | L13: FALSE | M13: https://www.gowid.com | N13: 698e6abe35dc2af1bcf2 | T13: native | W13: initial | Y13: waiting | AA13: FALSE | AB13: FALSE | AC13: FALSE | AD13: FALSE | AE13: TRUE | AJ13: 46072.679 | AK13: 46072.687 | AM13: 46072.679 | AN13: 46072.679 | CR13: https://desk.channel.io/gowid/user-chats/6996b8ff711dff23d7ae
A14: 6996b2968cf1975c3cb5 | B14: 46072.66 | C14: {=INDEX('User data'!E:E, MATCH(E14, 'User data'!B:B, 0))} | D14: {=INDEX('User data'!F:F, MATCH(C14, 'User data'!E:E, 0))} -> #N/A | E14: 팔레트 582 | J14: medium | K14: INBOUND | L14: FALSE | M14: https://www.gowid.com | N14: 6996a69cd3ca03317e6e | T14: native | W14: initial | Y14: waiting | AA14: FALSE | AB14: FALSE | AC14: FALSE | AD14: FALSE | AE14: TRUE | AJ14: 46072.66 | AK14: 46072.661 | AM14: 46072.66 | AN14: 46072.66 | CR14: https://desk.channel.io/gowid/user-chats/6996b2968cf1975c3cb5
A15: 6996b047df5bc0d1ba53 | B15: 46072.656 | C15: {=INDEX('User data'!E:E, MATCH(E15, 'User data'!B:B, 0))} -> 주식회사 트위넬 | D15: {=INDEX('User data'!F:F, MATCH(C15, 'User data'!E:E, 0))} -> 8388103911 | E15: 주식회사 트위넬 | H15: [상담요약] - 고객사: 고위드 - 문의요약: 멤버 정보 변경 요청 - 문의유형: 정보 수정 - impact: L2 - 처리내용: 회원가입 미완료 확인 - 결과: 정보 수정 불가 - 후속조치: 회원가입 완료 후 이메일로 변경 지원 | J15: medium | K15: OUTBOUND | L15: FALSE | N15: 6996af79a1277aaaf40a | O15: 607950 | P15: 607950 | R15: 607950 | T15: email | U15: email | W15: snoozed | Y15: waiting | AA15: TRUE | AB15: FALSE | AC15: FALSE | AD15: TRUE | AE15: FALSE | AF15: 1 | AG15: 1 | AJ15: 46072.653 | AK15: 46073.521 | AL15: 46072.657 | AM15: 46072.656 | AP15: 46072.657 | AT15: 46072.656 | AU15: 46073.518 | AX15: 46072.653 | AY15: 46072.656 | AZ15: 46072.661 | BA15: 46072.661 | BB15: 46073.521 | BE15: 377 | BF15: 377 | BG15: 377 | BH15: 377 | BI15: 14400 | BJ15: 8717 | BO15: 377 | BP15: 377 | BQ15: 377 | BR15: 377 | BS15: 670 | BT15: 670 | BU15: 377 | BV15: 377 | BW15: 377 | BX15: 377 | CO15: 3 | CR15: https://desk.channel.io/gowid/user-chats/6996b047df5bc0d1ba53
A16: 6996af7c373f0a18ddaf | B16: 46072.651 | C16: {=INDEX('User data'!E:E, MATCH(E16, 'User data'!B:B, 0))} -> 주식회사 트위넬 | D16: {=INDEX('User data'!F:F, MATCH(C16, 'User data'!E:E, 0))} -> 8388103911 | E16: 주식회사 트위넬 | H16: [상담요약] - 고객사: - 문의요약: 메일 주소 오류 - 문의유형: 정보 수정 요청 - impact: L1 - 처리내용: 고객의 메일 주소 확인, 멤버 정보 변경 요청 - 결과: 법인명과 사업자 번호 요청 - 후속조치: 고객의 추가 정보 대기 | J16: medium | K16: INBOUND | L16: FALSE | M16: https://gowid.channel.io | N16: 6996af79a1277aaaf40a | O16: 607950 | P16: 607950 | R16: 607950 | T16: native | W16: snoozed | Y16: waiting | AA16: TRUE | AB16: FALSE | AC16: FALSE | AD16: TRUE | AE16: TRUE | AF16: 1 | AG16: 1 | AJ16: 46072.651 | AK16: 46073.521 | AL16: 46072.652 | AM16: 46072.651 | AN16: 46072.651 | AO16: 46072.651 | AP16: 46072.652 | AT16: 46072.651 | AU16: 46073.518 | AX16: 46072.652 | AY16: 46072.651 | AZ16: 46072.652 | BA16: 46072.652 | BB16: 46073.521 | BE16: 69 | BF16: 69 | BG16: 69 | BH16: 69 | BI16: 14399 | BJ16: 8716 | BM16: 113 | BN16: 113 | BO16: 115 | BP16: 115 | BQ16: 115 | BR16: 115 | BS16: 1 | BT16: 1 | BU16: 69 | BV16: 69 | BW16: 69 | BX16: 69 | CO16: 3 | CP16: 2 | CR16: https://desk.channel.io/gowid/user-chats/6996af7c373f0a18ddaf
A17: 6996ac71bcd572c171f4 | B17: 46072.642 | C17: {=INDEX('User data'!E:E, MATCH(E17, 'User data'!B:B, 0))} -> 주식회사 오픈아이오티 | D17: {=INDEX('User data'!F:F, MATCH(C17, 'User data'!E:E, 0))} -> 175-88-03861 | E17: 김동은 | J17: medium | K17: INBOUND | L17: FALSE | M17: https://www.gowid.com | N17: 69857160abf7ab10bf7b | T17: native | W17: initial | Y17: waiting | AA17: FALSE | AB17: FALSE | AC17: FALSE | AD17: FALSE | AE17: TRUE | AJ17: 46072.641 | AK17: 46072.642 | AM17: 46072.642 | AN17: 46072.642 | CR17: https://desk.channel.io/gowid/user-chats/6996ac71bcd572c171f4
A18: 6996ac37bdf4850a6fb0 | B18: 46072.641 | C18: {=INDEX('User data'!E:E, MATCH(E18, 'User data'!B:B, 0))} -> 주식회사 아토즈소프트 | D18: {=INDEX('User data'!F:F, MATCH(C18, 'User data'!E:E, 0))} -> 117-81-81687 | E18: 서호진 | J18: medium | K18: INBOUND | L18: FALSE | M18: https://www.gowid.com | N18: 686c7842bdfc6fd158a6 | T18: native | W18: initial | Y18: waiting | AA18: FALSE | AB18: FALSE | AC18: FALSE | AD18: FALSE | AE18: TRUE | AJ18: 46072.641 | AK18: 46072.644 | AM18: 46072.641 | AN18: 46072.641 | CR18: https://desk.channel.io/gowid/user-chats/6996ac37bdf4850a6fb0
A19: 6996a8437d5b72bf1640 | B19: 46072.629 | C19: {=INDEX('User data'!E:E, MATCH(E19, 'User data'!B:B, 0))} -> 주식회사 아일로 | D19: {=INDEX('User data'!F:F, MATCH(C19, 'User data'!E:E, 0))} -> 322-88-02342 | E19: 류지현 | J19: medium | K19: INBOUND | L19: FALSE | M19: https://www.gowid.com | N19: 65d6a61a8181fd32e65c | T19: native | W19: initial | Y19: waiting | AA19: FALSE | AB19: FALSE | AC19: FALSE | AD19: FALSE | AE19: TRUE | AJ19: 46072.629 | AK19: 46072.629 | AM19: 46072.629 | AN19: 46072.629 | CR19: https://desk.channel.io/gowid/user-chats/6996a8437d5b72bf1640
A20: 6996a5d9e42382cabfa6 | B20: 46072.622 | C20: {=INDEX('User data'!E:E, MATCH(E20, 'User data'!B:B, 0))} -> (주)튜링 | D20: {=INDEX('User data'!F:F, MATCH(C20, 'User data'!E:E, 0))} -> 254-87-01382 | E20: 신지은 | J20: medium | K20: INBOUND | L20: FALSE | M20: https://gowid.channel.io | N20: 6711e6d10bd2776ab6b3 | T20: native | W20: initial | Y20: waiting | AA20: FALSE | AB20: FALSE | AC20: FALSE | AD20: FALSE | AE20: TRUE | AJ20: 46072.622 | AK20: 46072.622 | AM20: 46072.622 | AN20: 46072.622 | CR20: https://desk.channel.io/gowid/user-chats/6996a5d9e42382cabfa6
A21: 6996a5c85da03308cb7d | B21: 46072.622 | C21: {=INDEX('User data'!E:E, MATCH(E21, 'User data'!B:B, 0))} -> 주식회사 플루토 (PLUTO) | D21: {=INDEX('User data'!F:F, MATCH(C21, 'User data'!E:E, 0))} -> 444-87-02140 | E21: 양해민 | J21: medium | K21: INBOUND | L21: FALSE | M21: https://www.gowid.com | N21: 65d2e377ef7151c31c25 | T21: native | W21: initial | Y21: waiting | AA21: FALSE | AB21: FALSE | AC21: FALSE | AD21: FALSE | AE21: TRUE | AJ21: 46072.622 | AK21: 46072.622 | AM21: 46072.622 | AN21: 46072.622 | CR21: https://desk.channel.io/gowid/user-chats/6996a5c85da03308cb7d
A22: 6996a5821c6300cff115 | B22: 46072.621 | C22: {=INDEX('User data'!E:E, MATCH(E22, 'User data'!B:B, 0))} -> 주식회사 플루비(PLUVI Co.,Ltd) | D22: {=INDEX('User data'!F:F, MATCH(C22, 'User data'!E:E, 0))} -> 830-86-03552 | E22: 박준성 | J22: medium | K22: INBOUND | L22: FALSE | M22: https://www.gowid.com | N22: 696f31eeae4409bc6c96 | T22: native | W22: initial | Y22: waiting | AA22: FALSE | AB22: FALSE | AC22: FALSE | AD22: FALSE | AE22: TRUE | AJ22: 46072.621 | AK22: 46072.622 | AM22: 46072.621 | AN22: 46072.621 | CR22: https://desk.channel.io/gowid/user-chats/6996a5821c6300cff115
A23: 6996a3f63e6dfd8a17ef | B23: 46072.616 | C23: {=INDEX('User data'!E:E, MATCH(E23, 'User data'!B:B, 0))} -> (주)온차 | D23: {=INDEX('User data'!F:F, MATCH(C23, 'User data'!E:E, 0))} -> 799-81-02937 | E23: 정진미 | J23: medium | K23: INBOUND | L23: FALSE | M23: https://www.gowid.com | N23: 69967cd2267eb0097db1 | T23: native | W23: initial | Y23: waiting | AA23: FALSE | AB23: FALSE | AC23: FALSE | AD23: FALSE | AE23: TRUE | AJ23: 46072.616 | AK23: 46072.617 | AM23: 46072.616 | AN23: 46072.616 | CR23: https://desk.channel.io/gowid/user-chats/6996a3f63e6dfd8a17ef
A24: 6996a1db5dfe1fb7581c | B24: 46072.61 | C24: {=INDEX('User data'!E:E, MATCH(E24, 'User data'!B:B, 0))} -> 주식회사 솔로몬랩스(Solomon Labs Co., Ltd.) | D24: {=INDEX('User data'!F:F, MATCH(C24, 'User data'!E:E, 0))} -> 249-87-03675 | E24: 박다솜 | J24: medium | K24: INBOUND | L24: FALSE | M24: https://www.gowid.com | N24: 6909a9ef55643f86a4d0 | T24: native | W24: initial | Y24: waiting | AA24: FALSE | AB24: FALSE | AC24: FALSE | AD24: FALSE | AE24: TRUE | AJ24: 46072.61 | AK24: 46072.779 | AM24: 46072.61 | AN24: 46072.61 | CR24: https://desk.channel.io/gowid/user-chats/6996a1db5dfe1fb7581c
A25: 69969b9781793e8a72d7 | B25: 46072.592 | C25: {=INDEX('User data'!E:E, MATCH(E25, 'User data'!B:B, 0))} -> 주식회사 이터녹스 | D25: {=INDEX('User data'!F:F, MATCH(C25, 'User data'!E:E, 0))} -> 839-86-03001 | E25: 정한길 | J25: medium | K25: INBOUND | L25: FALSE | M25: https://www.gowid.com | N25: 6954cdaf9c0ee46a027b | T25: native | W25: initial | Y25: waiting | AA25: FALSE | AB25: FALSE | AC25: FALSE | AD25: FALSE | AE25: TRUE | AJ25: 46072.592 | AK25: 46072.593 | AM25: 46072.592 | AN25: 46072.592 | CR25: https://desk.channel.io/gowid/user-chats/69969b9781793e8a72d7
A26: 69969a5fe1fc17b96564 | B26: 46072.588 | C26: {=INDEX('User data'!E:E, MATCH(E26, 'User data'!B:B, 0))} -> 주식회사 스튜디오크립티드 | D26: {=INDEX('User data'!F:F, MATCH(C26, 'User data'!E:E, 0))} -> 329-86-02368 | E26: 백한열 | J26: medium | K26: INBOUND | L26: FALSE | M26: https://www.gowid.com | N26: 69969a3eada6ff84cc1d | T26: native | W26: initial | Y26: waiting | AA26: FALSE | AB26: FALSE | AC26: FALSE | AD26: FALSE | AE26: TRUE | AJ26: 46072.588 | AK26: 46072.588 | AM26: 46072.588 | AN26: 46072.588 | CR26: https://desk.channel.io/gowid/user-chats/69969a5fe1fc17b96564
A27: 6996945158bb08e6d581 | B27: 46072.57 | C27: {=INDEX('User data'!E:E, MATCH(E27, 'User data'!B:B, 0))} -> 주식회사 리훈 (RIHOON CO., LTD.) | D27: {=INDEX('User data'!F:F, MATCH(C27, 'User data'!E:E, 0))} -> 489-88-01777 | E27: 박이훈 | J27: medium | K27: INBOUND | L27: FALSE | M27: https://www.gowid.com | N27: 660b9ca16bc23e2402b8 | T27: native | W27: initial | Y27: waiting | AA27: FALSE | AB27: FALSE | AC27: FALSE | AD27: FALSE | AE27: TRUE | AJ27: 46072.57 | AK27: 46073.57 | AM27: 46072.57 | AN27: 46072.57 | CR27: https://desk.channel.io/gowid/user-chats/6996945158bb08e6d581
A28: 6996900cec4cc2ff1764 | B28: 46072.557 | C28: {=INDEX('User data'!E:E, MATCH(E28, 'User data'!B:B, 0))} -> 주식회사 브랜뉴에이전시 (Brand New Agency Inc.) | D28: {=INDEX('User data'!F:F, MATCH(C28, 'User data'!E:E, 0))} -> 639-87-02302 | E28: 서강민 | J28: medium | K28: INBOUND | L28: FALSE | M28: https://www.gowid.com | N28: 6684d193243ee7c2e826 | T28: native | W28: initial | Y28: waiting | AA28: FALSE | AB28: FALSE | AC28: FALSE | AD28: FALSE | AE28: TRUE | AJ28: 46072.557 | AK28: 46073.558 | AM28: 46072.557 | AN28: 46072.557 | CR28: https://desk.channel.io/gowid/user-chats/6996900cec4cc2ff1764
A29: 6996900132e6ee07c769 | B29: 46072.557 | C29: {=INDEX('User data'!E:E, MATCH(E29, 'User data'!B:B, 0))} -> 주식회사 브랜뉴에이전시 (Brand New Agency Inc.) | D29: {=INDEX('User data'!F:F, MATCH(C29, 'User data'!E:E, 0))} -> 639-87-02302 | E29: 서강민 | J29: medium | K29: INBOUND | L29: FALSE | M29: https://www.gowid.com | N29: 6684d193243ee7c2e826 | T29: native | W29: initial | Y29: waiting | AA29: FALSE | AB29: FALSE | AC29: FALSE | AD29: FALSE | AE29: TRUE | AJ29: 46072.557 | AK29: 46073.557 | AM29: 46072.557 | AN29: 46072.557 | CR29: https://desk.channel.io/gowid/user-chats/6996900132e6ee07c769
A30: 69968b6fc41146c130e6 | B30: 46072.544 | C30: {=INDEX('User data'!E:E, MATCH(E30, 'User data'!B:B, 0))} -> 주식회사 오가시스 (ORGASIS Corp.) | D30: {=INDEX('User data'!F:F, MATCH(C30, 'User data'!E:E, 0))} -> 531-87-02594 | E30: 황중식 | H30: 요약할 내용이 없습니다. | I30: 멤버관리(단순문의) | J30: medium | K30: INBOUND | L30: FALSE | M30: https://www.gowid.com | N30: 698d2dc165342e2d8c0e | O30: 574085 | P30: 574085 | Q30: 574085 | R30: 574085, 607950 | S30: 13285 | T30: native | W30: closed | Y30: waiting | AA30: TRUE | AB30: TRUE | AC30: FALSE | AD30: TRUE | AE30: TRUE | AF30: 5 | AG30: 4 | AH30: 1 | AJ30: 46072.544 | AK30: 46072.65 | AL30: 46072.544 | AM30: 46072.544 | AN30: 46072.544 | AO30: 46072.544 | AP30: 46072.544 | AQ30: 46072.544 | AS30: 46072.544 | AT30: 46072.544 | AU30: 46072.607 | AX30: 46072.544 | AY30: 46072.544 | AZ30: 46072.567 | BA30: 46072.58 | BB30: 46072.567 | BC30: 46072.599 | BD30: 46072.608 | BE30: 2462 | BF30: 484 | BG30: 492 | BH30: 121 | BI30: 7 | BJ30: 7 | BK30: 2 | BL30: 0 | BM30: 6 | BN30: 0 | BO30: 1983 | BP30: 387 | BQ30: 1983 | BR30: 387 | BS30: 1977 | BT30: 387 | BU30: 1977 | BV30: 387 | BW30: 1979 | BX30: 387 | BY30: 4755 | BZ30: 3159 | CA30: 5531 | CB30: 3935 | CC30: 4755 | CD30: 3159 | CE30: 4749 | CF30: 3159 | CG30: 4749 | CH30: 3159 | CI30: 4751 | CJ30: 3159 | CK30: 4809 | CL30: 3219 | CM30: 4741 | CN30: 3151 | CO30: 2 | CP30: 3 | CR30: https://desk.channel.io/gowid/user-chats/69968b6fc41146c130e6 | CS30: 5
A31: 6996812c771869e2e69b | B31: 46072.513 | C31: {=INDEX('User data'!E:E, MATCH(E31, 'User data'!B:B, 0))} | D31: {=INDEX('User data'!F:F, MATCH(C31, 'User data'!E:E, 0))} -> #N/A | E31: 팅커벨 026 | J31: medium | K31: INBOUND | L31: FALSE | M31: https://www.gowid.com | N31: 6996811f9fe00a4391fb | T31: native | W31: initial | Y31: waiting | AA31: FALSE | AB31: FALSE | AC31: FALSE | AD31: FALSE | AE31: TRUE | AJ31: 46072.513 | AK31: 46073.514 | AM31: 46072.513 | AN31: 46072.513 | CR31: https://desk.channel.io/gowid/user-chats/6996812c771869e2e69b
A32: 699680185446fb920981 | B32: 46072.51 | C32: {=INDEX('User data'!E:E, MATCH(E32, 'User data'!B:B, 0))} | D32: {=INDEX('User data'!F:F, MATCH(C32, 'User data'!E:E, 0))} -> #N/A | E32: 스타 325 | J32: medium | K32: INBOUND | L32: FALSE | M32: https://docs.channel.io/gowid-guide/ko/articles/고위드-법인카드-스펙-안내-a97b7c3f | N32: 698ed7de08d3482713fe | T32: native | W32: initial | Y32: waiting | AA32: FALSE | AB32: FALSE | AC32: FALSE | AD32: FALSE | AE32: TRUE | AJ32: 46072.51 | AK32: 46072.752 | AM32: 46072.51 | AN32: 46072.51 | CR32: https://desk.channel.io/gowid/user-chats/699680185446fb920981
A33: 69967bcfa966a7cf3c4d | B33: 46072.498 | C33: {=INDEX('User data'!E:E, MATCH(E33, 'User data'!B:B, 0))} -> 주식회사 디에프코퍼레이션 | D33: {=INDEX('User data'!F:F, MATCH(C33, 'User data'!E:E, 0))} -> 808-86-00446 | E33: 퍼스트캔버스 | J33: medium | K33: INBOUND | L33: FALSE | M33: https://www.gowid.com | N33: 67217a30884027249f64 | T33: native | W33: initial | Y33: waiting | AA33: FALSE | AB33: FALSE | AC33: FALSE | AD33: FALSE | AE33: TRUE | AJ33: 46072.497 | AK33: 46073.498 | AM33: 46072.498 | AN33: 46072.498 | CR33: https://desk.channel.io/gowid/user-chats/69967bcfa966a7cf3c4d
A34: 698d979a04d5b1245178 | B34: 46072.497 | C34: {=INDEX('User data'!E:E, MATCH(E34, 'User data'!B:B, 0))} -> 주식회사 플루토 (PLUTO) | D34: {=INDEX('User data'!F:F, MATCH(C34, 'User data'!E:E, 0))} -> 444-87-02140 | E34: 양해민 | H34: 상담 내용이 15글자 이하이므로 요약할 내용이 없습니다. | I34: 카드/한도상하향 | J34: medium | K34: OUTBOUND | L34: FALSE | N34: 65d2e377ef7151c31c25 | O34: 574085 | P34: 574085 | Q34: 574085 | R34: 574085, 607950 | T34: email | U34: email | W34: closed | Y34: none | AA34: TRUE | AB34: FALSE | AC34: FALSE | AD34: TRUE | AE34: FALSE | AF34: 2 | AG34: 2 | AJ34: 46065.753 | AK34: 46072.616 | AL34: 46072.498 | AM34: 46072.497 | AP34: 46072.498 | AT34: 46072.497 | AU34: 46072.567 | AX34: 46065.753 | AY34: 46072.497 | AZ34: 46072.504 | BA34: 46072.574 | BB34: 46072.507 | BC34: 46072.574 | BD34: 46072.574 | BE34: 1196 | BF34: 1196 | BG34: 598 | BH34: 598 | BI34: 5206 | BJ34: 1606 | BO34: 600 | BP34: 600 | BQ34: 601 | BR34: 601 | BS34: 583286 | BT34: 93952 | BU34: 600 | BV34: 600 | BW34: 600 | BX34: 600 | BY34: 6657 | BZ34: 3057 | CA34: 6657 | CB34: 3057 | CC34: 6657 | CD34: 3057 | CE34: 589342 | CF34: 96408 | CG34: 6657 | CH34: 3057 | CI34: 6657 | CJ34: 3057 | CK34: 1451 | CL34: 1451 | CM34: 1451 | CN34: 1451 | CO34: 3 | CR34: https://desk.channel.io/gowid/user-chats/698d979a04d5b1245178
A35: 69967b01ae8debaaf0de | B35: 46072.495 | C35: {=INDEX('User data'!E:E, MATCH(E35, 'User data'!B:B, 0))} -> 주식회사 스케일업스쿼드(SCALEUPSQUAD Corp.) | D35: {=INDEX('User data'!F:F, MATCH(C35, 'User data'!E:E, 0))} -> 413-86-02907 | E35: 박승표 | H35: - 고객사: 고위드 - 문의요약: 상담원 연결 요청 및 탄력 조정 적용 시기 문의 - 문의유형: 상담 요청 - impact: L2 - 처리내용: 상담원과 연결 요청 - 결과: 대기 중 - 후속조치: 추가 확인 필요 | I35: 구독/GWS | J35: medium | K35: INBOUND | L35: FALSE | M35: https://www.gowid.com | N35: 6728a0d15d906aa40765 | O35: 594863 | P35: 574085 | R35: 533671, 574085, 594863 | S35: 13285 | T35: native | W35: opened | Y35: waiting | AA35: TRUE | AB35: FALSE | AC35: TRUE | AD35: TRUE | AE35: TRUE | AF35: 1 | AG35: 1 | AI35: 1 | AJ35: 46072.495 | AK35: 46073.542 | AL35: 46072.497 | AM35: 46072.495 | AN35: 46072.495 | AO35: 46072.496 | AP35: 46072.497 | AQ35: 46072.496 | AS35: 46072.496 | AT35: 46072.496 | AU35: 46073.542 | AX35: 46072.496 | AY35: 46072.496 | AZ35: 46072.506 | BA35: 46072.506 | BB35: 46072.567 | BE35: 824 | BF35: 824 | BG35: 824 | BH35: 824 | BI35: 84229 | BJ35: 21219 | BK35: 0 | BL35: 0 | BM35: 94 | BN35: 94 | BO35: 918 | BP35: 918 | BQ35: 918 | BR35: 918 | BS35: 823 | BT35: 823 | BU35: 823 | BV35: 823 | BW35: 824 | BX35: 824 | CO35: 3 | CP35: 93 | CR35: https://desk.channel.io/gowid/user-chats/69967b01ae8debaaf0de
A36: 69967a4c2b07490a20c4 | B36: 46072.493 | C36: {=INDEX('User data'!E:E, MATCH(E36, 'User data'!B:B, 0))} -> 주식회사 스케일업스쿼드(SCALEUPSQUAD Corp.) | D36: {=INDEX('User data'!F:F, MATCH(C36, 'User data'!E:E, 0))} -> 413-86-02907 | E36: 박승표 | J36: medium | K36: INBOUND | L36: FALSE | M36: https://www.gowid.com | N36: 6728a0d15d906aa40765 | T36: native | W36: initial | Y36: waiting | AA36: FALSE | AB36: FALSE | AC36: FALSE | AD36: FALSE | AE36: TRUE | AJ36: 46072.493 | AK36: 46073.493 | AM36: 46072.493 | AN36: 46072.493 | CR36: https://desk.channel.io/gowid/user-chats/69967a4c2b07490a20c4
A37: 69967989eaefdf6b94b4 | B37: 46072.491 | C37: {=INDEX('User data'!E:E, MATCH(E37, 'User data'!B:B, 0))} -> 주식회사 코네이스 | D37: {=INDEX('User data'!F:F, MATCH(C37, 'User data'!E:E, 0))} -> 857-81-02868 | E37: 조명광 | H37: [상담요약] - 고객사: 롯데카드 - 문의요약: 카드 한도 상향 신청 진행 상황 - 문의유형: 승인 상태 문의 - impact: L2 - 처리내용: 신청 중인 카드 한도 상향 심사 확인 - 결과: 심사 차주 초 완료 예정, 메일 안내 예정 - 후속조치: 추가 문의 필요 시 새 창에서 문의 | I37: 카드/한도상하향 | J37: medium | K37: INBOUND | L37: FALSE | M37: https://www.gowid.com | N37: 695c9837cb14ff9fd3b6 | O37: 574085 | P37: 574085 | Q37: 574085 | R37: 574085, 607950 | S37: 13285 | T37: native | W37: closed | Y37: none | AA37: TRUE | AB37: FALSE | AC37: FALSE | AD37: TRUE | AE37: TRUE | AF37: 3 | AG37: 3 | AJ37: 46072.491 | AK37: 46072.548 | AL37: 46072.507 | AM37: 46072.491 | AN37: 46072.491 | AO37: 46072.504 | AQ37: 46072.504 | AS37: 46072.504 | AT37: 46072.504 | AU37: 46072.504 | AX37: 46072.504 | AY37: 46072.504 | AZ37: 46072.504 | BA37: 46072.506 | BC37: 46072.507 | BD37: 46072.507 | BE37: 67 | BF37: 67 | BG37: 22 | BH37: 22 | BK37: 1 | BL37: 1 | BM37: 1105 | BN37: 1105 | BO37: 1139 | BP37: 1139 | BQ37: 1139 | BR37: 1139 | BS37: 33 | BT37: 33 | BU37: 33 | BV37: 33 | BW37: 34 | BX37: 34 | BY37: 1340 | BZ37: 1340 | CA37: 1340 | CB37: 1340 | CC37: 1341 | CD37: 1341 | CE37: 235 | CF37: 235 | CG37: 235 | CH37: 235 | CI37: 236 | CJ37: 236 | CK37: 235 | CL37: 235 | CM37: 235 | CN37: 235 | CP37: 1104 | CR37: https://desk.channel.io/gowid/user-chats/69967989eaefdf6b94b4
A38: 699675ec3808cb178591 | B38: 46072.48 | C38: {=INDEX('User data'!E:E, MATCH(E38, 'User data'!B:B, 0))} -> 가제트코리아 주식회사 | D38: {=INDEX('User data'!F:F, MATCH(C38, 'User data'!E:E, 0))} -> 786-87-01837 | E38: 이현주 | H38: [상담요약] - 고객사: - 문의요약: 날짜 변경 및 라이선스 추가 요청 - 문의유형: 라이선스 변경 - impact: L2 - 처리내용: 3월 2일에서 3월 3일로 변경, 라이선스 3개 추가 요청 - 결과: 3월 3일 자정 3개 라이선스 추가 확정 - 후속조치: 세팅 진행 예정 | I38: 구독/GWS | J38: medium | K38: INBOUND | L38: FALSE | M38: https://www.gowid.com | N38: 691681b63ec1d5a14061 | O38: 594863 | P38: 607950 | Q38: 594863 | R38: 533671, 594863, 607950 | S38: 13288 | T38: native | W38: closed | Y38: none | AA38: TRUE | AB38: FALSE | AC38: TRUE | AD38: TRUE | AE38: TRUE | AF38: 7 | AG38: 6 | AI38: 1 | AJ38: 46072.48 | AK38: 46072.726 | AL38: 46072.572 | AM38: 46072.48 | AN38: 46072.48 | AO38: 46072.481 | AP38: 46072.572 | AT38: 46072.481 | AU38: 46072.571 | AX38: 46072.481 | AY38: 46072.481 | AZ38: 46072.481 | BA38: 46072.681 | BB38: 46072.567 | BC38: 46072.684 | BD38: 46072.684 | BE38: 14386 | BF38: 7602 | BG38: 2055 | BH38: 1267 | BI38: 355 | BJ38: 355 | BM38: 67 | BN38: 67 | BO38: 68 | BP38: 68 | BQ38: 68 | BR38: 68 | BS38: 0 | BT38: 0 | BU38: 20 | BV38: 20 | BW38: 20 | BX38: 20 | BY38: 17614 | BZ38: 14014 | CA38: 17614 | CB38: 14014 | CC38: 17614 | CD38: 14014 | CE38: 17547 | CF38: 13947 | CG38: 17567 | CH38: 13967 | CI38: 17567 | CJ38: 13967 | CK38: 17211 | CL38: 13611 | CM38: 17211 | CN38: 13611 | CO38: 3 | CP38: 47 | CR38: https://desk.channel.io/gowid/user-chats/699675ec3808cb178591
A39: 699675f5aa3871542499 | B39: 46072.48 | C39: {=INDEX('User data'!E:E, MATCH(E39, 'User data'!B:B, 0))} -> 주식회사 프롬프트타운 | D39: {=INDEX('User data'!F:F, MATCH(C39, 'User data'!E:E, 0))} -> 526-81-03003 | E39: 서진희 | J39: medium | K39: INBOUND | L39: FALSE | M39: https://www.gowid.com | N39: 685a5613b7d1c5e11ae5 | T39: native | W39: initial | Y39: waiting | AA39: FALSE | AB39: FALSE | AC39: FALSE | AD39: FALSE | AE39: TRUE | AJ39: 46072.48 | AK39: 46073.48 | AM39: 46072.48 | AN39: 46072.48 | CR39: https://desk.channel.io/gowid/user-chats/699675f5aa3871542499
A40: 699675b48a63d6b03ed4 | B40: 46072.479 | C40: {=INDEX('User data'!E:E, MATCH(E40, 'User data'!B:B, 0))} -> 헬로스킨 주식회사(HELLO SKIN Co.,Ltd.) | D40: {=INDEX('User data'!F:F, MATCH(C40, 'User data'!E:E, 0))} -> 888-88-00596 | E40: 지소영 | H40: 요약할 내용이 없습니다. | I40: 카드/한도상하향 | J40: medium | K40: INBOUND | L40: FALSE | M40: https://www.gowid.com | N40: 696db3205e96892e8e31 | O40: 574085 | P40: 574085 | Q40: 574085 | R40: 574085, 607950 | S40: 13285 | T40: native | W40: closed | Y40: none | AA40: TRUE | AB40: FALSE | AC40: FALSE | AD40: TRUE | AE40: TRUE | AF40: 2 | AG40: 2 | AJ40: 46072.479 | AK40: 46072.616 | AL40: 46072.574 | AM40: 46072.479 | AN40: 46072.479 | AO40: 46072.48 | AQ40: 46072.48 | AS40: 46072.48 | AT40: 46072.48 | AU40: 46072.567 | AX40: 46072.48 | AY40: 46072.48 | AZ40: 46072.481 | BA40: 46072.574 | BB40: 46072.567 | BC40: 46072.574 | BD40: 46072.574 | BE40: 656 | BF40: 656 | BG40: 328 | BH40: 328 | BI40: 20 | BJ40: 20 | BK40: 0 | BL40: 0 | BM40: 87 | BN40: 87 | BO40: 131 | BP40: 131 | BQ40: 131 | BR40: 131 | BS40: 44 | BT40: 44 | BU40: 43 | BV40: 43 | BW40: 44 | BX40: 44 | BY40: 8202 | BZ40: 4602 | CA40: 8202 | CB40: 4602 | CC40: 8202 | CD40: 4602 | CE40: 8115 | CF40: 4515 | CG40: 8115 | CH40: 4515 | CI40: 8115 | CJ40: 4515 | CK40: 8095 | CL40: 4495 | CM40: 8095 | CN40: 4495 | CP40: 87 | CR40: https://desk.channel.io/gowid/user-chats/699675b48a63d6b03ed4
...

Sheet Message data
A1: chatId | B1: personType | C1: personId | D1: createdAt | E1: plainText | F1: isPrivate
A2: 69707792ccb5efbface7 | B2: user | C2: 696db3205e96892e8e31 | D2: 46051.364 | E2: 안녕하세요. 고위드 신규 가입 상담 중인 헬로스킨 인사팀 지소영입니다. 전 직장에서 고위드 사용했어서 그대로 도입하고자 합니다. 1. 저희는 자체 기장을 하고 있지 않고 세무법인을 통해 기장 중입니다. 위하고를 사용하고 있는 것으로 전달 받았는데 고위드- 위하고 간 연결이 가능한가요? 2. 구글워크스페이스 도입을 하려고 합니다. (기존은 Google Workspace Enterprise Essentials 요금제를 쓰고 있습니다. 메일 기능이 없는 드라이브 용 요금제이나 엔터프라이즈 로 분류됐어서 리셀러사 문의시 스탠다드, 플러스 요금제에서 당장 큰 할인이 없었습니다. 고위드를 통해 구글워크스페이스 업그레이드를 진행하면 안내된 금액대로 이용이 가능한지요? 3. 구글 워크스페이스 기능 등에 대한 문의시 리셀러사처럼 안내를 받을 수 있나요? | F2: FALSE
A3: 69707792ccb5efbface7 | B3: user | C3: 696db3205e96892e8e31 | D3: 46051.37 | E3: 추가로 메일 마이그레이션 지원도 여쭤봅니다 | F3: FALSE
A4: 69707792ccb5efbface7 | B4: user | C4: 696db3205e96892e8e31 | D4: 46051.399 | E4: 기존 사용 사 기준 홈페이지상 견적이 공식홈페이지와 같은데 고위드 추가 할인이 없는 걸까요? | F4: FALSE
A5: 69707792ccb5efbface7 | B5: manager | C5: 574085 | D5: 46051.401 | E5: 소영님 안녕하세요, 고위드입니다. 우선 문의 주신 내용 중 1번 문의부터 답변 드리도록 하게습니다. 고위드에서는 카드 지출 내역을 더존-위하고 양식으로 다운로드 가능한 점 안내드립니다. 구독 관련 문의에 대해서는 담당자님 확인 후 안내드릴 수 있도록 하겠습니다. 감사합니다. | F5: FALSE
A6: 69707792ccb5efbface7 | B6: manager | C6: 574085 | D6: 46051.404 | E6: @고위드 김일경 매니저 일경님 구독 문의 들어왔습니다 | F6: TRUE
A7: 69707792ccb5efbface7 | B7: manager | C7: 594863 | D7: 46051.405 | E7: 넵! | F7: TRUE
A8: 69707792ccb5efbface7 | B8: manager | C8: 594863 | D8: 46051.414 | E8: 안녕하세요 지소영님 ☺️ 고위드 구독 서비스 김일경 매니저입니다. 구독 상품 관련 안내 드립니다. :) 1. 고위드를 통해 구글워크스페이스 업그레이드를 진행하면 안내된 금액대로 이용이 가능한지요? → 네, 비즈니스 요금제로 전환 하신 후 고위드 리셀러 신청을 해주시면 고위드 사이트에서 확인하실 수 있는 견적서대로 10%할인을 받으실 수 있습니다. 다만, 비즈니스 모델 특성 상 300명이 초과되는 인원은 상품 전환이 어려운 점 참고 부탁 드립니다. 2. 구글 워크스페이스 기능 등에 대한 문의시 리셀러사처럼 안내를 받을 수 있나요? → 네, 물론입니다. 기능 문의에 대한 부분은 담당자께서 상담을 통한 안내를 드리고 있습니다. 더해서, 고위드 구글워크스페이스는 버전 변경, 라이센스 수 변경을 고위드 홈페이지 내에서 진행 하실 수 있도록 서비스를 운영하고 있습니다. 이 외에도 기존에 사용하시던 모든 기능을 구글 콘솔을 통해서도 사용이 가능합니다. :) | F8: FALSE
A9: 69707792ccb5efbface7 | B9: user | C9: 696db3205e96892e8e31 | D9: 46051.424 | E9: 안녕하세요 - | F9: FALSE
A10: 69707792ccb5efbface7 | B10: user | C10: 696db3205e96892e8e31 | D10: 46051.424 | E10: 저희가 사용했던 요금제가 메일 기능이 없기는 하다 | F10: FALSE
A11: 69707792ccb5efbface7 | B11: user | C11: 696db3205e96892e8e31 | D11: 46051.424 | E11: 엔터프라이즈 에센셜로 명칭이있어 | F11: FALSE
A12: 69707792ccb5efbface7 | B12: user | C12: 696db3205e96892e8e31 | D12: 46051.424 | E12: 스탠다드로 변경하는 경우 '다운그레이드'라 | F12: FALSE
A13: 69707792ccb5efbface7 | B13: user | C13: 696db3205e96892e8e31 | D13: 46051.424 | E13: 할인가를 당장 받을 수 없다고 다른 리셀러사에서 연락을 받았습니다. | F13: FALSE
A14: 69707792ccb5efbface7 | B14: user | C14: 696db3205e96892e8e31 | D14: 46051.424 | E14: 고위드를 통하면 문제가 확실히 없는 것일까요? | F14: FALSE
A15: 69707792ccb5efbface7 | B15: user | C15: 696db3205e96892e8e31 | D15: 46051.425 | E15: 더하여, 공식 홈페이지 견적과 가격이 같게 나와서, | F15: FALSE
A16: 69707792ccb5efbface7 | B16: user | C16: 696db3205e96892e8e31 | D16: 46051.425 | E16: 저희는 신규 구글워크스페이스 도입이 아니어서 추가 할인이 안되는 것인지요? | F16: FALSE
A17: 69707792ccb5efbface7 | B17: manager | C17: 594863 | D17: 46051.425 | E17: 해당 내용 유선 통해 자세히 안내 드리면 더욱 좋을 것 같은데요! 희망 하시면 유선 문의로 전환 도와드릴까요? 아니면 채팅 답변도 가능합니다! | F17: FALSE
A18: 69707792ccb5efbface7 | B18: user | C18: 696db3205e96892e8e31 | D18: 46051.438 | E18: 오후 1시쯤에 통화 가능할까요? | F18: FALSE
A19: 69707792ccb5efbface7 | B19: user | C19: 696db3205e96892e8e31 | D19: 46051.438 | E19: 미팅이 있어서요 | F19: FALSE
A20: 69707792ccb5efbface7 | B20: manager | C20: 594863 | D20: 46051.438 | E20: 네! :) 13시 30분 경에 유선 안내 드릴 수 있도록 하겠습니다! 감사합니다. | F20: FALSE
A21: 69707792ccb5efbface7 | B21: user | C21: 696db3205e96892e8e31 | D21: 46051.439 | E21: 네 감사합니다 | F21: FALSE
A22: 69707792ccb5efbface7 | B22: manager | C22: 594863 | D22: 46051.44 | E22: 유선 안내 예정 | F22: TRUE
A23: 69707792ccb5efbface7 | B23: manager | C23: 594863 | D23: 46051.575 | E23: 유선으로 상담 마무리 되어 이번 상담은 여기서 종료하도록 하겠습니다. 다른 문의가 있으시면 새로운 창에서 문의 부탁드립니다. 좋은 하루 되시길 바랍니다 :) | F23: FALSE
A24: 6976bcf86eb9a25e8354 | B24: user | C24: 66946e4fa6ee2b22e45e | D24: 46048.419 | E24: 안녕하세요 법인카드 상향 신청 문의 드립니다. 1월 중 진행했었는데, 심사는 완료되었는데 계속하여 오류가 발생하는 것 같습니다. (동일 화면 재송신) 관련하여 확인 부탁 드립니다. 감사합니다. - 알리콘 주식회사 / 363-88-00097 - 법인카드 상향 심사 상황 및 가능여부 | F24: FALSE
A25: 6976bcf86eb9a25e8354 | B25: manager | C25: 506375 | D25: 46048.425 | E25: 안녕하세요 지은님, 고위드입니다. 불편을 드려 죄송합니다..! 내부적으로 확인 결과, 1/15 즈음 해당시기에 한도를 부여받기 어려우심을 안내받으신 것으로 확인되시는데요, 혹 지금 만나보시는 화면이 어떻게 되실까요? 오류일 시 확인 후 응대 도와드리고자 합니다! | F25: FALSE
A26: 6976bcf86eb9a25e8354 | B26: manager | C26: 506375 | D26: 46048.425 | E26: 상세하게 안내해드리기 위해 말씀해주신 증상에 대한 전체화면 캡쳐본을 보내주시면 감사하겠습니다. | F26: FALSE
A27: 6976c63b7ff568629b43 | B27: user | C27: 6971d94bc3ded889e1b9 | D27: 46048.447 | E27: 주주명부를 왜줘야하나요-->/ | F27: FALSE
A28: 6976c63b7ff568629b43 | B28: user | C28: 6971d94bc3ded889e1b9 | D28: 46048.447 | E28: 상담사연결 | F28: FALSE
A29: 6976c63b7ff568629b43 | B29: user | C29: 6971d94bc3ded889e1b9 | D29: 46048.447 | E29: 그냥 상담사연결해주세요 | F29: FALSE
A30: 6976c63b7ff568629b43 | B30: user | C30: 6971d94bc3ded889e1b9 | D30: 46048.447 | E30: 네 맞습니다 상담사연결해주세요 | F30: FALSE
A31: 6976c63b7ff568629b43 | B31: user | C31: 6971d94bc3ded889e1b9 | D31: 46048.448 | E31: 안녕하세요. | F31: FALSE
A32: 6976c63b7ff568629b43 | B32: user | C32: 6971d94bc3ded889e1b9 | D32: 46048.449 | E32: 주주명부를 왜전달해야하는지 모르겠어서 이야기드립니다. 그리고 저희회사는 싱가폴회사가 100%지분을가지고있는데 주주 명부가 필요할까요? | F32: FALSE
A33: 6976c63b7ff568629b43 | B33: manager | C33: 574085 | D33: 46048.451 | E33: 종빈님 안녕하세요, 고위드입니다. 법인 신용 카드 입회 시 금융소비자보호법에 따라 해당 법인의 실제 소유자를 확인하는 것은 필수 사항입니다. 이는 고위드 내부 정책이 아니라 카드사 입회 시 카드사에서 요구하는 필수 서류입니다. 더욱 정확한 안내를 위하여 법인께서 입회 희망하시는 카드사(신한/롯데/비씨 중)가 어디실지 여쭙습니다. | F33: FALSE
A34: 6976c63b7ff568629b43 | B34: user | C34: 6971d94bc3ded889e1b9 | D34: 46048.452 | E34: 롯데카드입니다 | F34: FALSE
A35: 6976c63b7ff568629b43 | B35: manager | C35: 574085 | D35: 46048.459 | E35: 롯데카드의 경우 1. 법인(A)의 최대 주주가 타 법인(B)일 경우, B법인의 주주명부 또한 요구하고 있습니다. 2. 다만 해외 법인으로 주주명부 수취가 불가할 경우 A법인 명의의 공문서를 통하여 갈음이 가능합니다. 주주명부 업로드하는 단계에서 1. 주식회사 라디우스랩의 주주명부 2. 주식회사 라디우스랩의 공문서 (최대 법인 주주명부 수취 불가) 를 함께 첨부하여 주시면 됩니다! 공문서 양식을 사진 첨부하여 함께 보내드리며, 수신에는 '롯데카드' 작성 부탁드립니다. | F35: FALSE
A36: 6976c63b7ff568629b43 | B36: manager | C36: 574085 | D36: 46048.46 | E36: 작성하셔야 하는 '롯데카드 실제소유자 확인서'에는 실제소유자 구분 > 3. '2항'을 확인할 수 없는 경우, 법인 또는 단체의 대표자 중 1인에 체크하여 주시고 아래 실제 소유자 정보에는 싱가포르 법인 정보 작성 부탁드립니다. | F36: FALSE
A37: 6976c63b7ff568629b43 | B37: manager | C37: 574085 | D37: 46048.468 | E37: 답장 오면 사실상 지배자 그 내용도 안내하기 | F37: TRUE
A38: 6976c63b7ff568629b43 | B38: user | C38: 6971d94bc3ded889e1b9 | D38: 46048.5 | E38: 여기서질문이 저희는 싱가폴 회사가 모회사이고 지금 현재 카드를 신청하는회사가 자회사입니다. | F38: FALSE
A39: 6976c63b7ff568629b43 | B39: user | C39: 6971d94bc3ded889e1b9 | D39: 46048.5 | E39: 이때는 싱가폴 회사인 모회사의 주주명부를 줘야하는건가요? | F39: FALSE
A40: 6976c63b7ff568629b43 | B40: manager | C40: 574085 | D40: 46048.502 | E40: 종빈님 혹시 유선으로 안내드려도 괜찮으실까요? 주주명부 관련 내용이 복잡하고, 최대 주주가 해외 법인일 경우 작성 방법이 별도로 있어 안내드리고자 합니다. 채널톡이 더 편하실 경우 제가 여기서 그대로 안내 도와드리도록 하겠습니다./ | F40: FALSE
...

Sheet User data
A1: id | B1: name | C1: profile.name | D1: profile.authorities | E1: profile.companyname | F1: profile.corp_number | G1: profile.coregroup | H1: profile.profile | I1: tags | J1: profile.email | K1: profile.mobileNumber | L1: profile.landlineNumber | M1: profile.description | N1: profile.firstName | O1: profile.lastName | P1: memberId | Q1: member | R1: sessionsCount | S1: city | T1: province | U1: country | V1: timeZone | W1: createdAt | X1: hasPushToken | Y1: language | Z1: lastSeenAt | AA1: profile.회사명 | AB1: mobile.appName | AC1: mobile.appVersion | AD1: mobile.device | AE1: mobile.lastSeenAt | AF1: mobile.os | AG1: mobile.osName | AH1: mobile.sessionsCount | AI1: unsubscribeEmail | AJ1: unsubscribeTexting | AK1: updatedAt | AL1: web.browser | AM1: web.browserName | AN1: web.device | AO1: web.lastSeenAt | AP1: web.os | AQ1: web.osName | AR1: web.sessionsCount | AS1: profile.lastCheckoutCompletedAt | AT1: profile.profileuserid | AU1: profile.referrer | AV1: profile.utmCampaign | AW1: profile.utmContent | AX1: profile.utmMedium | AY1: profile.utmSource | AZ1: profile.utmTerm | BA1: profile.kakaoProfileAgree | BB1: profile.ageRange | BC1: profile.birthday | BD1: profile.gender | BE1: hasChat | BF1: profile.lastUtmSource | BG1: profile.lastUtmMedium | BH1: profile.lastUtmCampaign | BI1: profile.lastUtmContent | BJ1: profile.lastUtmTerm | BK1: profile.lastReferrer | BL1: userImportTags
A2: 66dea44d813d143c976f | B2: 정재식 | C2: 정재식 | D2: EXPENSE:일반 멤버 / SUBSCRIPTION:구독 총괄 관리자 / CARD:일반 멤버 / FUEL:일반 멤버 | E2: 모비두 주식회사 (Mobidoo) | F2: 120-88-01596 | I2: 비회원 | J2: jace@mobidoo.co.kr | P2: 2085710732 | Q2: TRUE | R2: 340 | S2: 서울시 송파구 | U2: KR | V2: Asia/Seoul | W2: 2024-09-09T07:31:25.532Z | X2: FALSE | Y2: ko | Z2: 2026-02-20T04:51:44.003Z | AB2: com.gowid.expense | AC2: 2.8.4 | AD2: Apple iPhone | AE2: 2026-02-12T05:05:21.250Z | AF2: iOS 26.2.1 | AG2: iOS | AH2: 13 | AI2: FALSE | AJ2: FALSE | AK2: 2026-02-20T04:51:44.004Z | AL2: Chrome 145 | AM2: Chrome | AN2: Desktop | AO2: 2026-02-20T04:51:44.003Z | AP2: Windows NT ?? | AQ2: Windows NT | AR2: 327 | AU2: https://gowidsub.imweb.me/ | AV2: authority-01-2026 | AW2: gowid-card-image | AX2: paid-search | AY2: google | AZ2: 법인카드 | BE2: TRUE | BF2: google | BG2: paid-search | BH2: authority-01-2026 | BI2: gowid-card-image | BJ2: 법인카드 | BK2: https://www.google.com/
A3: 67e4dbda6a1c3cbc9018 | B3: 김시하(Fia) | C3: 김시하(Fia) | D3: EXPENSE:슈퍼관리자 / SUBSCRIPTION:구독 총괄 관리자 / CARD:슈퍼관리자 | E3: 주식회사 스위트스팟 | F3: 846-86-00225 | I3: 기가입회원/관리자/기존, 핵심고객(8월), 코어그룹, 코어그룹(12월) | J3: fiakim@sweetspot.co.kr | K3: =+821095736591 -> 821095736591 | P3: 111347732 | Q3: TRUE | R3: 198 | S3: 서울시 영등포구 | U3: KR | V3: Asia/Seoul | W3: 2025-03-27T05:02:18.434Z | X3: FALSE | Y3: ko | Z3: 2026-02-15T01:16:58.867Z | AB3: com.gowid.expense | AC3: 2.8.4 | AD3: Apple iPhone | AE3: 2026-02-14T07:20:51.476Z | AF3: iOS 18.7.1 | AG3: iOS | AH3: 9 | AI3: FALSE | AJ3: FALSE | AK3: 2026-02-15T01:16:58.868Z | AL3: Edge 144 | AM3: Edge | AN3: Desktop | AO3: 2026-02-15T01:16:58.867Z | AP3: Windows >=10 | AQ3: Windows NT | AR3: 189 | AU3: https://payment-gateway.tosspayments.com/ | BE3: TRUE | BK3: https://payment-gateway.tosspayments.com/
A4: 66f527f368aa3851799c | B4: 한재희 | C4: 한재희 | D4: EXPENSE:슈퍼관리자 / CARD:슈퍼관리자 | E4: 주식회사 호아파트너스 | F4: 650-86-01021 | J4: jh.han@eatech.kr | K4: =+821026927481 -> 821026927481 | P4: 2085747850 | Q4: TRUE | R4: 59 | S4: 서울시 강서구 | U4: KR | V4: Asia/Seoul | W4: 2024-09-26T09:22:59.428Z | X4: FALSE | Y4: ko | Z4: 2026-02-13T08:09:44.046Z | AI4: FALSE | AJ4: FALSE | AK4: 2026-02-13T08:09:44.047Z | AL4: Chrome 144 | AM4: Chrome | AN4: Apple Macintosh | AO4: 2026-02-13T08:09:44.046Z | AP4: Mac OS >=10.15.7 | AQ4: Mac OS | AR4: 59 | AU4: https://www.google.com/ | BE4: TRUE | BK4: https://www.google.com/ | BL4: 2025_11_11_channcel_talk_user
A5: 697c660d7bc0033871c1 | B5: 전기범 | C5: 전기범 | D5: CARD:슈퍼관리자 | E5: 주식회사 씨앤디 | F5: 858-87-01942 | I5: 비회원 | J5: cnd3700@cnd.ai | K5: =+821058510346 -> 821058510346 | P5: 108835543 | Q5: TRUE | R5: 1 | S5: 인천시 미추홀구 | U5: KR | V5: Asia/Seoul | W5: 2026-01-30T08:04:29.506Z | X5: FALSE | Y5: ko | Z5: 2026-01-30T08:04:29.506Z | AI5: FALSE | AJ5: FALSE | AK5: 2026-01-30T08:07:38.900Z | AL5: Chrome 144 | AM5: Chrome | AN5: Desktop | AO5: 2026-01-30T08:04:29.506Z | AP5: Windows NT ?? | AQ5: Windows NT | AR5: 1 | BE5: TRUE
A6: 670f25d79ec63a60565b | B6: 김선중 | C6: 김선중 | D6: EXPENSE:슈퍼관리자 / SUBSCRIPTION:구독 총괄 관리자 / CARD:슈퍼관리자 | E6: 버킷히어로(주) | F6: 561-88-03382 | I6: 기가입회원/관리자/신규, 기가입회원/관리자/기존 | J6: kevin.kim@buckethero.net | K6: =+821055252890 -> 821055252890 | P6: 110205691 | Q6: TRUE | R6: 46 | S6: 광주시 서구 | U6: KR | V6: Asia/Seoul | W6: 2024-10-16T02:32:55.649Z | X6: FALSE | Y6: ko | Z6: 2026-02-05T01:45:18.325Z | AI6: FALSE | AJ6: FALSE | AK6: 2026-02-05T01:45:18.326Z | AL6: Chrome 144 | AM6: Chrome | AN6: Apple Macintosh | AO6: 2026-02-05T01:45:18.325Z | AP6: Mac OS >=10.15.7 | AQ6: Mac OS | AR6: 46 | AU6: https://www.google.com/ | BE6: TRUE | BK6: https://www.google.com/ | BL6: 2025_11_11_channcel_talk_user
A7: 66d5bcc2bccdaa760422 | B7: 이재훈 | C7: 이재훈 | D7: EXPENSE:슈퍼관리자 / FUEL:슈퍼관리자 / SUBSCRIPTION:구독 총괄 관리자 / CARD:슈퍼관리자 | E7: 주식회사 콘스탄트 | F7: 517-87-01809 | I7: 기가입회원/관리자/기존 | J7: jaehoon@theconst.kr | P7: 2085707427 | Q7: TRUE | R7: 109 | S7: 서울시 마포구 | U7: KR | V7: Asia/Seoul | W7: 2024-09-02T13:25:22.773Z | X7: FALSE | Y7: ko | Z7: 2026-02-12T03:25:24.519Z | AI7: FALSE | AJ7: FALSE | AK7: 2026-02-12T03:25:24.520Z | AL7: Chrome 144 | AM7: Chrome | AN7: Desktop | AO7: 2026-02-12T01:27:02.211Z | AP7: Windows NT ?? | AQ7: Windows NT | AR7: 109 | AU7: https://www.google.com/ | BE7: TRUE | BK7: https://www.google.com/
A8: 6704c9ffda4cc452af14 | B8: 전혜림 | C8: 전혜림 | D8: EXPENSE:슈퍼관리자 / SUBSCRIPTION:구독 총괄 관리자 / CARD:슈퍼관리자 | E8: 주식회사 어글리랩 | F8: 524-86-02323 | I8: 기가입회원/관리자/기존 | J8: mayj@uglee.io | K8: =+821027901704 -> 821027901704 | P8: 111104222 | Q8: TRUE | R8: 474 | S8: 서울시 강남구 | U8: KR | V8: Asia/Seoul | W8: 2024-10-08T05:58:23.893Z | X8: FALSE | Y8: ko | Z8: 2026-02-20T04:35:48.215Z | AB8: com.gowid.expense | AC8: 2.8.4 | AD8: Samsung SM-S901N | AE8: 2026-02-15T05:35:21.157Z | AF8: Android 16 | AG8: Android | AH8: 4 | AI8: FALSE | AJ8: FALSE | AK8: 2026-02-20T04:35:48.216Z | AL8: Chrome 145 | AM8: Chrome | AN8: Desktop | AO8: 2026-02-20T04:35:48.215Z | AP8: Windows NT ?? | AQ8: Windows NT | AR8: 470 | AU8: https://search.naver.com/search.naver?sm=tab_hty.top&where=nexearch&ssc=tab.nx.all&query=%EA%B3%A0%EC%9C%84%EB%93%9C&oquery=%EA%B0%9C%EC%9D%B8%EB%B2%95%EC%9D%B8%EC%B9%B4%EB%93%9C&tqi=iwg5VsqVOsVssS1mLswssssssLV-064300 | AY8: blog | BE8: TRUE | BK8: https://gowidsub.imweb.me/
A9: 659cd039610cffa631f0 | B9: 박정웅 | C9: 박정웅 | D9: EXPENSE:슈퍼관리자 / CARD:슈퍼관리자 | E9: 주식회사 엔스프링 | F9: 119-86-45571 | I9: 기가입회원/관리자/신규, 기가입회원/관리자/기존 | J9: sevocard@sorizava.co.kr | K9: =+821047669733 -> 821047669733 | P9: 2085878501 | Q9: TRUE | R9: 46 | S9: 경기도 의정부시 | U9: KR | V9: Asia/Seoul | W9: 2024-01-09T04:48:57.396Z | X9: FALSE | Y9: ko | Z9: 2026-02-20T02:17:12.553Z | AI9: FALSE | AJ9: FALSE | AK9: 2026-02-20T02:17:12.554Z | AL9: Edge 145 | AM9: Edge | AN9: Desktop | AO9: 2026-02-20T02:17:12.553Z | AP9: Windows >=10 | AQ9: Windows NT | AR9: 46 | AU9: https://timbel.hanbiro.net/ | BE9: TRUE | BK9: https://docs.channel.io/ | BL9: 2025_11_11_channcel_talk_user
A10: 6567f0cce1fd1a752da6 | B10: 김가희 | C10: 김가희 | D10: EXPENSE:카드 총괄관리자 / CARD:카드 총괄관리자 | E10: 주식회사 디카르고 | F10: 419-81-02593 | I10: 기가입회원/관리자/기존 | J10: ghkim@dkargo.io | K10: =+821022652604 -> 821022652604 | P10: 108798736 | Q10: TRUE | R10: 2187 | S10: 서울시 강남구 | U10: KR | V10: Asia/Seoul | W10: 2023-11-30T02:17:48.925Z | X10: FALSE | Y10: ko | Z10: 2026-02-20T04:48:44.194Z | AB10: com.gowid.expense | AC10: 2.8.4 | AD10: Apple iPhone | AE10: 2026-02-19T15:25:54.308Z | AF10: iOS 26.2.1 | AG10: iOS | AH10: 219 | AI10: FALSE | AJ10: FALSE | AK10: 2026-02-20T04:48:44.195Z | AL10: Chrome 144 | AM10: Chrome | AN10: Desktop | AO10: 2026-02-20T04:48:44.194Z | AP10: Windows NT ?? | AQ10: Windows NT | AR10: 1968 | AU10: https://www.google.com/ | BE10: TRUE | BK10: https://search.naver.com/
A11: 677c706e82ccffebf4fc | B11: 정승익 | C11: 정승익 | D11: EXPENSE:슈퍼관리자 / CARD:슈퍼관리자 | E11: 아티움그룹 주식회사 | F11: 677-88-02368 | J11: cole0914@naver.com | K11: =+821095622198 -> 821095622198 | P11: 109016472 | Q11: TRUE | R11: 8 | S11: 서울시 마포구 | U11: KR | V11: Asia/Seoul | W11: 2025-01-07T00:08:14.535Z | X11: FALSE | Y11: ko | Z11: 2026-02-14T01:31:21.930Z | AI11: FALSE | AJ11: FALSE | AK11: 2026-02-14T01:31:21.931Z | AL11: Chrome 145 | AM11: Chrome | AN11: Desktop | AO11: 2026-02-14T01:31:21.930Z | AP11: Windows NT ?? | AQ11: Windows NT | AR11: 8 | AU11: https://search.naver.com/search.naver?ie=UTF-8&query=%EA%B3%A0%EC%9C%84%EB%93%9C&sm=chr_hty | AV11: card-apply | AW11: PC-light-251117-NBS-V1 | AX11: paid-search | AY11: naver | AZ11: 고위드 | BE11: TRUE | BF11: naver | BG11: paid-search | BH11: card-apply | BI11: PC-light-251117-NBS-V1 | BJ11: 고위드 | BK11: https://search.naver.com/ | BL11: 2025_11_11_channcel_talk_user
A12: 6995e3139d837d45c49f | B12: 지니 217 | P12: 12f84356-4872-442f-a003-481458c6e03a | Q12: FALSE | R12: 1 | S12: 서울시 성북구 | U12: KR | V12: Asia/Seoul | W12: 2026-02-18T16:04:35.644Z | X12: FALSE | Y12: ko | Z12: 2026-02-18T16:04:35.644Z | AI12: FALSE | AJ12: FALSE | AK12: 2026-02-18T16:04:35.644Z | AL12: Chrome 145 | AM12: Chrome | AN12: Android Mobile | AO12: 2026-02-18T16:04:35.644Z | AP12: Android ?? | AQ12: Android | AR12: 1 | AU12: https://www.google.com/ | BE12: TRUE | BK12: https://www.google.com/
A13: 67ff486731e439b1d270 | B13: 김산회 | C13: 김산회 | D13: EXPENSE:슈퍼관리자 / CARD:슈퍼관리자 | E13: 주식회사 굿컨설팅그룹 | F13: 525-87-00418 | I13: 기가입회원/관리자/기존 | J13: james.kim@goodconsulting.co.kr | K13: =+821044659835 -> 821044659835 | P13: 111387286 | Q13: TRUE | R13: 144 | S13: 경기도 과천시 | U13: KR | V13: Asia/Seoul | W13: 2025-04-16T06:04:23.204Z | X13: FALSE | Y13: ko | Z13: 2026-02-12T06:04:23.151Z | AI13: FALSE | AJ13: FALSE | AK13: 2026-02-12T06:04:23.152Z | AL13: Chrome 144 | AM13: Chrome | AN13: Apple Macintosh | AO13: 2026-02-12T06:04:23.151Z | AP13: Mac OS >=10.15.7 | AQ13: Mac OS | AR13: 144 | AU13: https://www.google.com/ | AV13: authority-01-2026 | AW13: gowid-card-image | AX13: paid-search | AY13: google | AZ13: 법인카드 | BE13: TRUE | BF13: google | BG13: paid-search | BH13: authority-01-2026 | BI13: gowid-card-image | BJ13: 법인카드 | BK13: https://www.google.com/ | BL13: 2025_11_11_channcel_talk_user
A14: 697f58630b8b911f2f5a | B14: 다트 445 | P14: 73c08cab-7ff0-41c0-946d-4f102d4159dd | Q14: FALSE | R14: 4 | S14: 서울시 중구 | U14: KR | V14: Asia/Seoul | W14: 2026-02-01T13:42:59.047Z | X14: FALSE | Y14: ko | Z14: 2026-02-09T10:09:23.634Z | AI14: FALSE | AJ14: FALSE | AK14: 2026-02-09T10:09:23.635Z | AL14: Chrome 145.0.7632.41 | AM14: Chrome | AN14: Apple iPhone | AO14: 2026-02-09T10:09:23.634Z | AP14: iOS 26.2.1 | AQ14: iOS | AR14: 4 | AV14: 120242291175170606 | AW14: 120242291175200606 | AX14: paid | AY14: ig | AZ14: 120242291175180606 | BE14: TRUE | BF14: ig | BG14: social | BH14: 120242291175170606 | BI14: link_in_bio | BJ14: 120242291175180606
A15: 6971d94bc3ded889e1b9 | B15: 한종빈 | C15: 한종빈 | D15: CARD:슈퍼관리자 / SUBSCRIPTION:구독 총괄 관리자 / EXPENSE:슈퍼관리자 | E15: 주식회사 라디우스랩 | F15: 567-87-02875 | I15: 기가입회원/관리자/신규, 기가입회원/소지자 | J15: stompesi@theradius.xyz | K15: =+821041920787 -> 821041920787 | P15: 122956855 | Q15: TRUE | R15: 37 | S15: 서울시 송파구 | U15: KR | V15: Asia/Seoul | W15: 2026-01-22T08:01:15.802Z | X15: FALSE | Y15: ko | Z15: 2026-02-20T03:17:43.623Z | AB15: com.gowid.expense | AC15: 2.8.4 | AD15: Samsung SM-F966N | AE15: 2026-02-20T03:17:43.623Z | AF15: Android 16 | AG15: Android | AH15: 5 | AI15: FALSE | AJ15: FALSE | AK15: 2026-02-20T03:17:43.623Z | AL15: Chrome 144 | AM15: Chrome | AN15: Apple Macintosh | AO15: 2026-02-20T01:42:14.453Z | AP15: Mac OS >=10.15.7 | AQ15: Mac OS | AR15: 32 | AU15: https://www.google.com/ | BE15: TRUE | BK15: https://www.google.com/
A16: 67217a30884027249f64 | B16: 퍼스트캔버스 | C16: 퍼스트캔버스 | D16: EXPENSE:슈퍼관리자 / CARD:슈퍼관리자 | E16: 주식회사 디에프코퍼레이션 | F16: 808-86-00446 | I16: 기가입회원/관리자/기존, 코어그룹(12월) | J16: tax@firstcanvas.co.kr | K16: =+821023180446 -> 821023180446 | P16: 114618587 | Q16: TRUE | R16: 360 | S16: 서울시 마포구 | U16: KR | V16: Asia/Seoul | W16: 2024-10-30T00:13:36.558Z | X16: FALSE | Y16: ko | Z16: 2026-02-20T03:47:10.986Z | AB16: com.gowid.expense | AC16: 2.8.4 | AD16: Samsung SM-F766N | AE16: 2026-02-03T05:12:16.006Z | AF16: Android 16 | AG16: Android | AH16: 2 | AI16: FALSE | AJ16: FALSE | AK16: 2026-02-20T03:47:10.986Z | AL16: Edge 145 | AM16: Edge | AN16: Desktop | AO16: 2026-02-20T03:47:10.986Z | AP16: Windows >=10 | AQ16: Windows NT | AR16: 358 | AU16: https://www.google.com/ | BE16: TRUE | BK16: https://www.google.com/
A17: 670367117c4099b897f1 | B17: Jiny | C17: Jiny | D17: EXPENSE:슈퍼관리자 / CARD:슈퍼관리자 | E17: 주식회사 마크비전코리아 | F17: 490-81-01666 | I17: 기가입회원/관리자/기존 | J17: jiny.jang@marqvision.com | K17: =+821020383139 -> 821020383139 | P17: 111199985 | Q17: TRUE | R17: 364 | S17: 서울시 강남구 | U17: KR | V17: Asia/Seoul | W17: 2024-10-07T04:44:01.509Z | X17: FALSE | Y17: ko | Z17: 2026-02-13T07:20:46.746Z | AB17: com.gowid.expense | AC17: 2.8.4 | AD17: Apple iPhone | AE17: 2026-02-12T04:36:51.597Z | AF17: iOS 26.1 | AG17: iOS | AH17: 30 | AI17: FALSE | AJ17: FALSE | AK17: 2026-02-13T07:20:46.747Z | AL17: Firefox 147.0 | AM17: Firefox | AN17: Apple Macintosh | AO17: 2026-02-13T07:20:46.746Z | AP17: Mac OS >=10.15.7 | AQ17: Mac OS | AR17: 334 | BE17: TRUE
A18: 6996c313ed0bfe931579 | B18: 풋볼 754 | P18: 738f7f9b-8968-4158-a908-dd8c8c2e22a1 | Q18: FALSE | R18: 2 | S18: 서울시 강남구 | U18: KR | V18: Asia/Seoul | W18: 2026-02-19T08:00:19.971Z | X18: FALSE | Y18: ko | Z18: 2026-02-19T08:34:12.127Z | AI18: FALSE | AJ18: FALSE | AK18: 2026-02-19T08:34:12.127Z | AL18: Chrome 144 | AM18: Chrome | AN18: Desktop | AO18: 2026-02-19T08:34:12.127Z | AP18: Windows NT ?? | AQ18: Windows NT | AR18: 2 | AU18: https://www.google.com/ | BE18: TRUE | BK18: https://www.google.com/
A19: 66fd348332a7248106d9 | B19: 조윤주 | C19: 조윤주 | D19: EXPENSE:슈퍼관리자 / SUBSCRIPTION:구독 총괄 관리자 / CARD:슈퍼관리자 | E19: (주)자비스앤빌런즈 | F19: 158-86-00171 | I19: 기가입회원/관리자/기존, 핵심고객(8월), 코어그룹(12월) | J19: yunjoo@jobis.co | K19: =+821052308627 -> 821052308627 | P19: 110126994 | Q19: TRUE | R19: 986 | S19: 서울시 강남구 | U19: KR | V19: Asia/Seoul | W19: 2024-10-02T11:54:43.207Z | X19: FALSE | Y19: ko | Z19: 2026-02-19T07:12:41.571Z | AB19: com.gowid.expense | AC19: 2.8.4 | AD19: Apple iPhone | AE19: 2026-02-18T12:31:43.441Z | AF19: iOS 18.5 | AG19: iOS | AH19: 93 | AI19: TRUE | AJ19: TRUE | AK19: 2026-02-19T07:12:41.572Z | AL19: Chrome 144 | AM19: Chrome | AN19: Desktop | AO19: 2026-02-19T07:12:41.571Z | AP19: Windows NT ?? | AQ19: Windows NT | AR19: 893 | AU19: https://search.naver.com/search.naver?where=nexearch&sm=top_hty&fbm=0&ie=utf8&query=%EA%B3%A0%EC%9C%84%EB%93%9C | BE19: TRUE | BK19: https://search.naver.com/search.naver?where=nexearch&sm=top_hty&fbm=0&ie=utf8&query=%EA%B3%A0%EC%9C%84%EB%93%9C&ackey=ol7i18k7
A20: 6551dbb105b66add6f86 | B20: 임찬솔 | C20: 임찬솔 | D20: EXPENSE:슈퍼관리자 / CARD:슈퍼관리자 / SUBSCRIPTION:구독 총괄 관리자 | E20: 주식회사 열다컴퍼니 | F20: 793-87-02566 | H20: 신한 | I20: 기가입회원/관리자/기존 | J20: contact@yolda.kr | K20: =+821089585520 -> 821089585520 | P20: 116707327 | Q20: TRUE | R20: 290 | S20: 서울시 광진구 | U20: KR | V20: Asia/Seoul | W20: 2023-11-13T08:17:53.023Z | X20: FALSE | Y20: ko | Z20: 2026-02-19T14:45:54.902Z | AB20: com.gowid.expense | AC20: 2.7.3 | AD20: Samsung SM-S908N | AE20: 2026-01-28T04:00:09.635Z | AF20: Android 16 | AG20: Android | AH20: 2 | AI20: FALSE | AJ20: FALSE | AK20: 2026-02-19T14:45:54.904Z | AL20: Chrome 144 | AM20: Chrome | AN20: Apple Macintosh | AO20: 2026-02-19T14:45:54.902Z | AP20: Mac OS >=10.15.7 | AQ20: Mac OS | AR20: 288 | AU20: https://www.google.com/ | AV20: authority-01-2026 | AW20: gowid-card-image | AX20: paid-search | AY20: google | AZ20: 법인카드 | BE20: TRUE | BF20: google | BG20: paid-search | BH20: authority-01-2026 | BI20: gowid-card-image | BJ20: 법인카드 | BK20: https://www.google.com/
A21: 65921f1b05254de39656 | B21: 정민진 | C21: 정민진 | D21: EXPENSE:슈퍼관리자 / SUBSCRIPTION:구독 총괄 관리자 / CARD:슈퍼관리자 | E21: 주식회사 데이탄소프트 | F21: 326-88-01855 | I21: 기가입회원/관리자/기존, 비회원 | J21: support@datansoft.com | K21: =+821022249844 -> 821022249844 | P21: 114654591 | Q21: TRUE | R21: 177 | S21: 제주도 제주시 | U21: KR | V21: Asia/Seoul | W21: 2024-01-01T02:10:35.024Z | X21: FALSE | Y21: ko | Z21: 2026-02-19T03:03:16.975Z | AB21: com.gowid.expense | AC21: 2.8.4 | AD21: Samsung SM-S926N | AE21: 2026-02-19T03:03:16.975Z | AF21: Android 16 | AG21: Android | AH21: 50 | AI21: FALSE | AJ21: FALSE | AK21: 2026-02-19T03:03:16.976Z | AL21: Chrome 144 | AM21: Chrome | AN21: Desktop | AO21: 2026-02-09T00:33:06.203Z | AP21: Windows NT ?? | AQ21: Windows NT | AR21: 127 | AU21: https://corp.lottecard.co.kr/ | BE21: TRUE | BK21: https://www.bing.com/
A22: 67809d4aa7314954c090 | B22: young | C22: young | D22: EXPENSE:슈퍼관리자 / SUBSCRIPTION:구독 총괄 관리자 / CARD:슈퍼관리자 | E22: 주식회사 마이프랜차이즈 | F22: 584-87-01610 | I22: 기가입회원/관리자/신규, 기가입회원/관리자/기존 | J22: dayoung@myfranchise.kr | P22: 115593138 | Q22: TRUE | R22: 66 | S22: 서울시 서초구 | U22: KR | V22: Asia/Seoul | W22: 2025-01-10T04:08:42.684Z | X22: FALSE | Y22: ko | Z22: 2026-02-18T23:52:53.665Z | AB22: com.gowid.expense | AC22: 2.8.4 | AD22: Samsung SM-F956N | AE22: 2026-02-13T05:26:07.041Z | AF22: Android 16 | AG22: Android | AH22: 22 | AI22: FALSE | AJ22: FALSE | AK22: 2026-02-18T23:52:53.666Z | AL22: Chrome 145 | AM22: Chrome | AN22: Desktop | AO22: 2026-02-18T23:52:53.665Z | AP22: Windows NT ?? | AQ22: Windows NT | AR22: 44 | AU22: https://payment-gateway.tosspayments.com/ | BE22: TRUE | BK22: https://gowidsub.imweb.me/
A23: 67481f2a7b45d3666f5e | B23: 심상보 | C23: 심상보 | D23: EXPENSE:슈퍼관리자 / SUBSCRIPTION:구독 총괄 관리자 / CARD:슈퍼관리자 | E23: 주식회사 브릿센트(BRITCENT Inc.) | F23: 850-87-01711 | H23: 신한 | I23: 기가입회원/관리자/신규, 기가입회원/관리자/기존 | J23: britcent@britcent.com | K23: =+821049633616 -> 821049633616 | P23: 111202206 | Q23: TRUE | R23: 58 | S23: 서울시 중구 | U23: KR | V23: Asia/Seoul | W23: 2024-11-28T07:43:38.504Z | X23: FALSE | Y23: ko | Z23: 2026-01-31T14:09:41.263Z | AB23: com.gowid.expense | AC23: 2.8.3 | AD23: Apple iPhone | AE23: 2026-01-29T17:43:40.945Z | AF23: iOS 26.1 | AG23: iOS | AH23: 1 | AI23: FALSE | AJ23: FALSE | AK23: 2026-01-31T14:09:41.264Z | AL23: Chrome 144 | AM23: Chrome | AN23: Apple Macintosh | AO23: 2026-01-31T14:09:41.263Z | AP23: Mac OS >=10.15.7 | AQ23: Mac OS | AR23: 57 | AU23: https://www.google.com/ | AY23: blog | BE23: TRUE | BF23: blog | BK23: https://www.google.com/ | BL23: 2025_11_11_channcel_talk_user
